Workbook

Sheet Start here
A1: Half Marathon Plan, race on Sat Feb 6, 2027
A2: 15 weeks from Mon Oct 26, 2026. Same plan as the web app and the full plan document.
A3: Days to race | B3: =MAX(0,DATE(2027,2,6)-TODAY()) -> 104
A5: Your inputs (yellow cells)
A6: Max heart rate (bpm) | B6: 194 | E6: Highest seen in your Strava data (10K on Aug 7, 2026). Change it if you see higher.
A7: Starting VDOT (Base phase) | B7: 32 | E7: From your 5K 28:26 (Feb 4) and 10K 59:54 (Aug 7).
A8: 5K test, Sat Nov 21: minutes / seconds | E8: Example: 27 in the first box and 50 in the second for 27:50.
A9: 10K test, Sat Dec 19: minutes / seconds | E9: Example: 58 and 30 for 58:30. Over an hour? Enter 61 and 5 for 1:01:05.
A11: What your tests say
A12: VDOT from 5K test | B12: =IF(N(B8)=0,"",MAX(30,29+SUMPRODUCT(--(Paces!$B$5:$B$15>=TIME(0,B8,N(C8)))))) | E12: Rounded down to the VDOT row your time reaches (Daniels, table 5.1).
A13: VDOT from 10K test | B13: =IF(N(B9)=0,"",MAX(30,29+SUMPRODUCT(--(Paces!$C$5:$C$15>=TIME(0,B9,N(C9))))))
A14: Build-phase VDOT (weeks 5–9) | B14: =IF(B12="",B7,B12) -> 32
A15: Race-phase VDOT (weeks 10–15) | B15: =IF(B13="",B14,B13) -> 32
A16: Predicted half marathon | B16: =INDEX(Paces!$D$5:$D$15,MATCH(B15,Paces!$A$5:$A$15,0)) -> 0.092928241 | E16: Plan target: 2:07:16 (VDOT 34). Stretch: 2:04:13 (VDOT 35).
A17: Half-marathon pace | B17: =INDEX(Paces!$E$5:$E$15,MATCH(B15,Paces!$A$5:$A$15,0)) -> 6:21/km
A19: How to use it
A20: 1. Plan sheet: one row per day. Target paces update from your VDOT in the yellow cells above.
A21: 2. After each run, set Done to Yes and fill in Actual km, Time, Avg HR, Feel (1 very easy to 5 very hard) and Notes.
A22: 3. Type time as h:mm:ss, for example 0:41:20. Typing 41:20 means 41 hours in Excel and Google Sheets.
A23: 4. Weekly sheet totals planned and logged km for each week and charts them.
A24: 5. Move up a VDOT only after a test, and not more often than every third week (Daniels).
A26: Example of a logged run (copy the format into the Plan sheet)
A27: Done | B27: Actual km | C27: Time | D27: Avg HR | E27: Feel (1–5) | F27: Notes
A28: Yes | B28: 6.7 | C28: 0.028703704 | D28: 158 | E28: 3 | F28: Humid; reps felt controlled
A30: Links
A31: Web app (phone) | B31: https://pengkistan.github.io/marathonplan/
A32: Full plan with sources | B32: https://claude.ai/artifact/BErnvi4zztgJg9Htm676nq

Sheet Plan
A1: Date | B1: Week | C1: Phase | D1: Day | E1: Session | F1: Workout | G1: Planned km | H1: VDOT | I1: Target | J1: Done | K1: Actual km | L1: Time | M1: Avg HR | N1: Feel (1–5) | O1: Pace /km | P1: Notes | Q1: Key
A2: 46321 | B2: 1 | C2: Base | D2: Mon | E2: Rest | F2: Rest day. Optional 10 min core at home on Mon or Fri. | H2: =IF(C2="Base",'Start here'!$B$7,IF(C2="Build",'Start here'!$B$14,'Start here'!$B$15)) -> 32 | I2: =IF(Q2="","",IF(Q2="E","HR under "&ROUND('Start here'!$B$6*0.79,0),IF(Q2="REC","HR under "&ROUND('Start here'!$B$6*0.76,0),IF(Q2="L","HR "&ROUND('Start here'!$B$6*0.73,0)&" to "&ROUND('Start here'!$B$6*0.84,0),INDEX(Paces!$B$5:$K$15,MATCH(H2,Paces!$A$5:$A$15,0),MATCH(Q2,Paces!$B$4:$K$4,0)))))) | O2: =IF(AND(N(K2)>0,N(L2)>0),L2/K2,"")
A3: 46322 | B3: 1 | C3: Base | D3: Tue | E3: Threshold | F3: 2 km easy · 3 × 1 km at T, 1 min jog · 1.5 km easy | G3: 6.7 | H3: =IF(C3="Base",'Start here'!$B$7,IF(C3="Build",'Start here'!$B$14,'Start here'!$B$15)) -> 32 | I3: =IF(Q3="","",IF(Q3="E","HR under "&ROUND('Start here'!$B$6*0.79,0),IF(Q3="REC","HR under "&ROUND('Start here'!$B$6*0.76,0),IF(Q3="L","HR "&ROUND('Start here'!$B$6*0.73,0)&" to "&ROUND('Start here'!$B$6*0.84,0),INDEX(Paces!$B$5:$K$15,MATCH(H3,Paces!$A$5:$A$15,0),MATCH(Q3,Paces!$B$4:$K$4,0)))))) -> 6:05/km | O3: =IF(AND(N(K3)>0,N(L3)>0),L3/K3,"") | Q3: T pace
A4: 46323 | B4: 1 | C4: Base | D4: Wed | E4: Easy + strides | F4: Easy 35 min + 6 strides | G4: 4.6 | H4: =IF(C4="Base",'Start here'!$B$7,IF(C4="Build",'Start here'!$B$14,'Start here'!$B$15)) -> 32 | I4: =IF(Q4="","",IF(Q4="E","HR under "&ROUND('Start here'!$B$6*0.79,0),IF(Q4="REC","HR under "&ROUND('Start here'!$B$6*0.76,0),IF(Q4="L","HR "&ROUND('Start here'!$B$6*0.73,0)&" to "&ROUND('Start here'!$B$6*0.84,0),INDEX(Paces!$B$5:$K$15,MATCH(H4,Paces!$A$5:$A$15,0),MATCH(Q4,Paces!$B$4:$K$4,0)))))) -> HR under 153 | O4: =IF(AND(N(K4)>0,N(L4)>0),L4/K4,"") | Q4: E
A5: 46324 | B5: 1 | C5: Base | D5: Thu | E5: Easy + hill sprints | F5: Easy 35 min + 2 hill sprints (8 s) | G5: 4.3 | H5: =IF(C5="Base",'Start here'!$B$7,IF(C5="Build",'Start here'!$B$14,'Start here'!$B$15)) -> 32 | I5: =IF(Q5="","",IF(Q5="E","HR under "&ROUND('Start here'!$B$6*0.79,0),IF(Q5="REC","HR under "&ROUND('Start here'!$B$6*0.76,0),IF(Q5="L","HR "&ROUND('Start here'!$B$6*0.73,0)&" to "&ROUND('Start here'!$B$6*0.84,0),INDEX(Paces!$B$5:$K$15,MATCH(H5,Paces!$A$5:$A$15,0),MATCH(Q5,Paces!$B$4:$K$4,0)))))) -> HR under 153 | O5: =IF(AND(N(K5)>0,N(L5)>0),L5/K5,"") | Q5: E
A6: 46325 | B6: 1 | C6: Base | D6: Fri | E6: Rest | F6: Rest day. Optional 10 min core at home on Mon or Fri. | H6: =IF(C6="Base",'Start here'!$B$7,IF(C6="Build",'Start here'!$B$14,'Start here'!$B$15)) -> 32 | I6: =IF(Q6="","",IF(Q6="E","HR under "&ROUND('Start here'!$B$6*0.79,0),IF(Q6="REC","HR under "&ROUND('Start here'!$B$6*0.76,0),IF(Q6="L","HR "&ROUND('Start here'!$B$6*0.73,0)&" to "&ROUND('Start here'!$B$6*0.84,0),INDEX(Paces!$B$5:$K$15,MATCH(H6,Paces!$A$5:$A$15,0),MATCH(Q6,Paces!$B$4:$K$4,0)))))) | O6: =IF(AND(N(K6)>0,N(L6)>0),L6/K6,"")
A7: 46326 | B7: 1 | C7: Base | D7: Sat | E7: Long run | F7: Long 12 km easy, early morning | G7: 12 | H7: =IF(C7="Base",'Start here'!$B$7,IF(C7="Build",'Start here'!$B$14,'Start here'!$B$15)) -> 32 | I7: =IF(Q7="","",IF(Q7="E","HR under "&ROUND('Start here'!$B$6*0.79,0),IF(Q7="REC","HR under "&ROUND('Start here'!$B$6*0.76,0),IF(Q7="L","HR "&ROUND('Start here'!$B$6*0.73,0)&" to "&ROUND('Start here'!$B$6*0.84,0),INDEX(Paces!$B$5:$K$15,MATCH(H7,Paces!$A$5:$A$15,0),MATCH(Q7,Paces!$B$4:$K$4,0)))))) -> HR 142 to 163 | O7: =IF(AND(N(K7)>0,N(L7)>0),L7/K7,"") | Q7: L
A8: 46327 | B8: 1 | C8: Base | D8: Sun | E8: Recovery | F8: Recovery 30 min | G8: 3.6 | H8: =IF(C8="Base",'Start here'!$B$7,IF(C8="Build",'Start here'!$B$14,'Start here'!$B$15)) -> 32 | I8: =IF(Q8="","",IF(Q8="E","HR under "&ROUND('Start here'!$B$6*0.79,0),IF(Q8="REC","HR under "&ROUND('Start here'!$B$6*0.76,0),IF(Q8="L","HR "&ROUND('Start here'!$B$6*0.73,0)&" to "&ROUND('Start here'!$B$6*0.84,0),INDEX(Paces!$B$5:$K$15,MATCH(H8,Paces!$A$5:$A$15,0),MATCH(Q8,Paces!$B$4:$K$4,0)))))) -> HR under 147 | O8: =IF(AND(N(K8)>0,N(L8)>0),L8/K8,"") | Q8: REC
A9: 46328 | B9: 2 | C9: Base | D9: Mon | E9: Rest | F9: Rest day. Optional 10 min core at home on Mon or Fri. | H9: =IF(C9="Base",'Start here'!$B$7,IF(C9="Build",'Start here'!$B$14,'Start here'!$B$15)) -> 32 | I9: =IF(Q9="","",IF(Q9="E","HR under "&ROUND('Start here'!$B$6*0.79,0),IF(Q9="REC","HR under "&ROUND('Start here'!$B$6*0.76,0),IF(Q9="L","HR "&ROUND('Start here'!$B$6*0.73,0)&" to "&ROUND('Start here'!$B$6*0.84,0),INDEX(Paces!$B$5:$K$15,MATCH(H9,Paces!$A$5:$A$15,0),MATCH(Q9,Paces!$B$4:$K$4,0)))))) | O9: =IF(AND(N(K9)>0,N(L9)>0),L9/K9,"")
A10: 46329 | B10: 2 | C10: Base | D10: Tue | E10: Threshold | F10: 2 km easy · 2 × 1.6 km at T, 2 min jog · 1.5 km easy | G10: 7 | H10: =IF(C10="Base",'Start here'!$B$7,IF(C10="Build",'Start here'!$B$14,'Start here'!$B$15)) -> 32 | I10: =IF(Q10="","",IF(Q10="E","HR under "&ROUND('Start here'!$B$6*0.79,0),IF(Q10="REC","HR under "&ROUND('Start here'!$B$6*0.76,0),IF(Q10="L","HR "&ROUND('Start here'!$B$6*0.73,0)&" to "&ROUND('Start here'!$B$6*0.84,0),INDEX(Paces!$B$5:$K$15,MATCH(H10,Paces!$A$5:$A$15,0),MATCH(Q10,Paces!$B$4:$K$4,0)))))) -> 6:05/km | O10: =IF(AND(N(K10)>0,N(L10)>0),L10/K10,"") | Q10: T pace
A11: 46330 | B11: 2 | C11: Base | D11: Wed | E11: Easy + strides | F11: Easy 40 min + 6 strides | G11: 5.2 | H11: =IF(C11="Base",'Start here'!$B$7,IF(C11="Build",'Start here'!$B$14,'Start here'!$B$15)) -> 32 | I11: =IF(Q11="","",IF(Q11="E","HR under "&ROUND('Start here'!$B$6*0.79,0),IF(Q11="REC","HR under "&ROUND('Start here'!$B$6*0.76,0),IF(Q11="L","HR "&ROUND('Start here'!$B$6*0.73,0)&" to "&ROUND('Start here'!$B$6*0.84,0),INDEX(Paces!$B$5:$K$15,MATCH(H11,Paces!$A$5:$A$15,0),MATCH(Q11,Paces!$B$4:$K$4,0)))))) -> HR under 153 | O11: =IF(AND(N(K11)>0,N(L11)>0),L11/K11,"") | Q11: E
A12: 46331 | B12: 2 | C12: Base | D12: Thu | E12: Easy + hill sprints | F12: Easy 35 min + 4 hill sprints (8 s) | G12: 4.4 | H12: =IF(C12="Base",'Start here'!$B$7,IF(C12="Build",'Start here'!$B$14,'Start here'!$B$15)) -> 32 | I12: =IF(Q12="","",IF(Q12="E","HR under "&ROUND('Start here'!$B$6*0.79,0),IF(Q12="REC","HR under "&ROUND('Start here'!$B$6*0.76,0),IF(Q12="L","HR "&ROUND('Start here'!$B$6*0.73,0)&" to "&ROUND('Start here'!$B$6*0.84,0),INDEX(Paces!$B$5:$K$15,MATCH(H12,Paces!$A$5:$A$15,0),MATCH(Q12,Paces!$B$4:$K$4,0)))))) -> HR under 153 | O12: =IF(AND(N(K12)>0,N(L12)>0),L12/K12,"") | Q12: E
A13: 46332 | B13: 2 | C13: Base | D13: Fri | E13: Rest | F13: Rest day. Optional 10 min core at home on Mon or Fri. | H13: =IF(C13="Base",'Start here'!$B$7,IF(C13="Build",'Start here'!$B$14,'Start here'!$B$15)) -> 32 | I13: =IF(Q13="","",IF(Q13="E","HR under "&ROUND('Start here'!$B$6*0.79,0),IF(Q13="REC","HR under "&ROUND('Start here'!$B$6*0.76,0),IF(Q13="L","HR "&ROUND('Start here'!$B$6*0.73,0)&" to "&ROUND('Start here'!$B$6*0.84,0),INDEX(Paces!$B$5:$K$15,MATCH(H13,Paces!$A$5:$A$15,0),MATCH(Q13,Paces!$B$4:$K$4,0)))))) | O13: =IF(AND(N(K13)>0,N(L13)>0),L13/K13,"")
A14: 46333 | B14: 2 | C14: Base | D14: Sat | E14: Long run | F14: Long 12 km easy | G14: 12 | H14: =IF(C14="Base",'Start here'!$B$7,IF(C14="Build",'Start here'!$B$14,'Start here'!$B$15)) -> 32 | I14: =IF(Q14="","",IF(Q14="E","HR under "&ROUND('Start here'!$B$6*0.79,0),IF(Q14="REC","HR under "&ROUND('Start here'!$B$6*0.76,0),IF(Q14="L","HR "&ROUND('Start here'!$B$6*0.73,0)&" to "&ROUND('Start here'!$B$6*0.84,0),INDEX(Paces!$B$5:$K$15,MATCH(H14,Paces!$A$5:$A$15,0),MATCH(Q14,Paces!$B$4:$K$4,0)))))) -> HR 142 to 163 | O14: =IF(AND(N(K14)>0,N(L14)>0),L14/K14,"") | Q14: L
A15: 46334 | B15: 2 | C15: Base | D15: Sun | E15: Recovery | F15: Recovery 30 min | G15: 3.6 | H15: =IF(C15="Base",'Start here'!$B$7,IF(C15="Build",'Start here'!$B$14,'Start here'!$B$15)) -> 32 | I15: =IF(Q15="","",IF(Q15="E","HR under "&ROUND('Start here'!$B$6*0.79,0),IF(Q15="REC","HR under "&ROUND('Start here'!$B$6*0.76,0),IF(Q15="L","HR "&ROUND('Start here'!$B$6*0.73,0)&" to "&ROUND('Start here'!$B$6*0.84,0),INDEX(Paces!$B$5:$K$15,MATCH(H15,Paces!$A$5:$A$15,0),MATCH(Q15,Paces!$B$4:$K$4,0)))))) -> HR under 147 | O15: =IF(AND(N(K15)>0,N(L15)>0),L15/K15,"") | Q15: REC
A16: 46335 | B16: 3 | C16: Base | D16: Mon | E16: Rest | F16: Rest day. Optional 10 min core at home on Mon or Fri. | H16: =IF(C16="Base",'Start here'!$B$7,IF(C16="Build",'Start here'!$B$14,'Start here'!$B$15)) -> 32 | I16: =IF(Q16="","",IF(Q16="E","HR under "&ROUND('Start here'!$B$6*0.79,0),IF(Q16="REC","HR under "&ROUND('Start here'!$B$6*0.76,0),IF(Q16="L","HR "&ROUND('Start here'!$B$6*0.73,0)&" to "&ROUND('Start here'!$B$6*0.84,0),INDEX(Paces!$B$5:$K$15,MATCH(H16,Paces!$A$5:$A$15,0),MATCH(Q16,Paces!$B$4:$K$4,0)))))) | O16: =IF(AND(N(K16)>0,N(L16)>0),L16/K16,"")
A17: 46336 | B17: 3 | C17: Base | D17: Tue | E17: Threshold | F17: 2 km easy · 4 × 5 min at T, 1 min jog · 1.5 km easy | G17: 7.1 | H17: =IF(C17="Base",'Start here'!$B$7,IF(C17="Build",'Start here'!$B$14,'Start here'!$B$15)) -> 32 | I17: =IF(Q17="","",IF(Q17="E","HR under "&ROUND('Start here'!$B$6*0.79,0),IF(Q17="REC","HR under "&ROUND('Start here'!$B$6*0.76,0),IF(Q17="L","HR "&ROUND('Start here'!$B$6*0.73,0)&" to "&ROUND('Start here'!$B$6*0.84,0),INDEX(Paces!$B$5:$K$15,MATCH(H17,Paces!$A$5:$A$15,0),MATCH(Q17,Paces!$B$4:$K$4,0)))))) -> 6:05/km | O17: =IF(AND(N(K17)>0,N(L17)>0),L17/K17,"") | Q17: T pace
A18: 46337 | B18: 3 | C18: Base | D18: Wed | E18: Easy + strides | F18: Easy 40 min + 8 strides | G18: 5.3 | H18: =IF(C18="Base",'Start here'!$B$7,IF(C18="Build",'Start here'!$B$14,'Start here'!$B$15)) -> 32 | I18: =IF(Q18="","",IF(Q18="E","HR under "&ROUND('Start here'!$B$6*0.79,0),IF(Q18="REC","HR under "&ROUND('Start here'!$B$6*0.76,0),IF(Q18="L","HR "&ROUND('Start here'!$B$6*0.73,0)&" to "&ROUND('Start here'!$B$6*0.84,0),INDEX(Paces!$B$5:$K$15,MATCH(H18,Paces!$A$5:$A$15,0),MATCH(Q18,Paces!$B$4:$K$4,0)))))) -> HR under 153 | O18: =IF(AND(N(K18)>0,N(L18)>0),L18/K18,"") | Q18: E
A19: 46338 | B19: 3 | C19: Base | D19: Thu | E19: Easy + hill sprints | F19: Easy 40 min + 6 hill sprints (8 s) | G19: 5 | H19: =IF(C19="Base",'Start here'!$B$7,IF(C19="Build",'Start here'!$B$14,'Start here'!$B$15)) -> 32 | I19: =IF(Q19="","",IF(Q19="E","HR under "&ROUND('Start here'!$B$6*0.79,0),IF(Q19="REC","HR under "&ROUND('Start here'!$B$6*0.76,0),IF(Q19="L","HR "&ROUND('Start here'!$B$6*0.73,0)&" to "&ROUND('Start here'!$B$6*0.84,0),INDEX(Paces!$B$5:$K$15,MATCH(H19,Paces!$A$5:$A$15,0),MATCH(Q19,Paces!$B$4:$K$4,0)))))) -> HR under 153 | O19: =IF(AND(N(K19)>0,N(L19)>0),L19/K19,"") | Q19: E
A20: 46339 | B20: 3 | C20: Base | D20: Fri | E20: Rest | F20: Rest day. Optional 10 min core at home on Mon or Fri. | H20: =IF(C20="Base",'Start here'!$B$7,IF(C20="Build",'Start here'!$B$14,'Start here'!$B$15)) -> 32 | I20: =IF(Q20="","",IF(Q20="E","HR under "&ROUND('Start here'!$B$6*0.79,0),IF(Q20="REC","HR under "&ROUND('Start here'!$B$6*0.76,0),IF(Q20="L","HR "&ROUND('Start here'!$B$6*0.73,0)&" to "&ROUND('Start here'!$B$6*0.84,0),INDEX(Paces!$B$5:$K$15,MATCH(H20,Paces!$A$5:$A$15,0),MATCH(Q20,Paces!$B$4:$K$4,0)))))) | O20: =IF(AND(N(K20)>0,N(L20)>0),L20/K20,"")
A21: 46340 | B21: 3 | C21: Base | D21: Sat | E21: Long run | F21: Long 13 km easy | G21: 13 | H21: =IF(C21="Base",'Start here'!$B$7,IF(C21="Build",'Start here'!$B$14,'Start here'!$B$15)) -> 32 | I21: =IF(Q21="","",IF(Q21="E","HR under "&ROUND('Start here'!$B$6*0.79,0),IF(Q21="REC","HR under "&ROUND('Start here'!$B$6*0.76,0),IF(Q21="L","HR "&ROUND('Start here'!$B$6*0.73,0)&" to "&ROUND('Start here'!$B$6*0.84,0),INDEX(Paces!$B$5:$K$15,MATCH(H21,Paces!$A$5:$A$15,0),MATCH(Q21,Paces!$B$4:$K$4,0)))))) -> HR 142 to 163 | O21: =IF(AND(N(K21)>0,N(L21)>0),L21/K21,"") | Q21: L
A22: 46341 | B22: 3 | C22: Base | D22: Sun | E22: Recovery | F22: Recovery 30 min | G22: 3.6 | H22: =IF(C22="Base",'Start here'!$B$7,IF(C22="Build",'Start here'!$B$14,'Start here'!$B$15)) -> 32 | I22: =IF(Q22="","",IF(Q22="E","HR under "&ROUND('Start here'!$B$6*0.79,0),IF(Q22="REC","HR under "&ROUND('Start here'!$B$6*0.76,0),IF(Q22="L","HR "&ROUND('Start here'!$B$6*0.73,0)&" to "&ROUND('Start here'!$B$6*0.84,0),INDEX(Paces!$B$5:$K$15,MATCH(H22,Paces!$A$5:$A$15,0),MATCH(Q22,Paces!$B$4:$K$4,0)))))) -> HR under 147 | O22: =IF(AND(N(K22)>0,N(L22)>0),L22/K22,"") | Q22: REC
A23: 46342 | B23: 4 | C23: Base | D23: Mon | E23: Rest | F23: Rest day. Optional 10 min core at home on Mon or Fri. | H23: =IF(C23="Base",'Start here'!$B$7,IF(C23="Build",'Start here'!$B$14,'Start here'!$B$15)) -> 32 | I23: =IF(Q23="","",IF(Q23="E","HR under "&ROUND('Start here'!$B$6*0.79,0),IF(Q23="REC","HR under "&ROUND('Start here'!$B$6*0.76,0),IF(Q23="L","HR "&ROUND('Start here'!$B$6*0.73,0)&" to "&ROUND('Start here'!$B$6*0.84,0),INDEX(Paces!$B$5:$K$15,MATCH(H23,Paces!$A$5:$A$15,0),MATCH(Q23,Paces!$B$4:$K$4,0)))))) | O23: =IF(AND(N(K23)>0,N(L23)>0),L23/K23,"")
A24: 46343 | B24: 4 | C24: Base | D24: Tue | E24: Threshold | F24: 2 km easy · 3 × 1 km at T, 1 min jog · 1.5 km easy | G24: 6.7 | H24: =IF(C24="Base",'Start here'!$B$7,IF(C24="Build",'Start here'!$B$14,'Start here'!$B$15)) -> 32 | I24: =IF(Q24="","",IF(Q24="E","HR under "&ROUND('Start here'!$B$6*0.79,0),IF(Q24="REC","HR under "&ROUND('Start here'!$B$6*0.76,0),IF(Q24="L","HR "&ROUND('Start here'!$B$6*0.73,0)&" to "&ROUND('Start here'!$B$6*0.84,0),INDEX(Paces!$B$5:$K$15,MATCH(H24,Paces!$A$5:$A$15,0),MATCH(Q24,Paces!$B$4:$K$4,0)))))) -> 6:05/km | O24: =IF(AND(N(K24)>0,N(L24)>0),L24/K24,"") | Q24: T pace
A25: 46344 | B25: 4 | C25: Base | D25: Wed | E25: Easy + strides | F25: Easy 35 min + 6 strides (skip Gym B this week) | G25: 4.6 | H25: =IF(C25="Base",'Start here'!$B$7,IF(C25="Build",'Start here'!$B$14,'Start here'!$B$15)) -> 32 | I25: =IF(Q25="","",IF(Q25="E","HR under "&ROUND('Start here'!$B$6*0.79,0),IF(Q25="REC","HR under "&ROUND('Start here'!$B$6*0.76,0),IF(Q25="L","HR "&ROUND('Start here'!$B$6*0.73,0)&" to "&ROUND('Start here'!$B$6*0.84,0),INDEX(Paces!$B$5:$K$15,MATCH(H25,Paces!$A$5:$A$15,0),MATCH(Q25,Paces!$B$4:$K$4,0)))))) -> HR under 153 | O25: =IF(AND(N(K25)>0,N(L25)>0),L25/K25,"") | Q25: E
A26: 46345 | B26: 4 | C26: Base | D26: Thu | E26: Easy + strides | F26: Easy 30 min + 4 strides | G26: 3.9 | H26: =IF(C26="Base",'Start here'!$B$7,IF(C26="Build",'Start here'!$B$14,'Start here'!$B$15)) -> 32 | I26: =IF(Q26="","",IF(Q26="E","HR under "&ROUND('Start here'!$B$6*0.79,0),IF(Q26="REC","HR under "&ROUND('Start here'!$B$6*0.76,0),IF(Q26="L","HR "&ROUND('Start here'!$B$6*0.73,0)&" to "&ROUND('Start here'!$B$6*0.84,0),INDEX(Paces!$B$5:$K$15,MATCH(H26,Paces!$A$5:$A$15,0),MATCH(Q26,Paces!$B$4:$K$4,0)))))) -> HR under 153 | O26: =IF(AND(N(K26)>0,N(L26)>0),L26/K26,"") | Q26: E
A27: 46346 | B27: 4 | C27: Base | D27: Fri | E27: Rest | F27: Rest day. Optional 10 min core at home on Mon or Fri. | H27: =IF(C27="Base",'Start here'!$B$7,IF(C27="Build",'Start here'!$B$14,'Start here'!$B$15)) -> 32 | I27: =IF(Q27="","",IF(Q27="E","HR under "&ROUND('Start here'!$B$6*0.79,0),IF(Q27="REC","HR under "&ROUND('Start here'!$B$6*0.76,0),IF(Q27="L","HR "&ROUND('Start here'!$B$6*0.73,0)&" to "&ROUND('Start here'!$B$6*0.84,0),INDEX(Paces!$B$5:$K$15,MATCH(H27,Paces!$A$5:$A$15,0),MATCH(Q27,Paces!$B$4:$K$4,0)))))) | O27: =IF(AND(N(K27)>0,N(L27)>0),L27/K27,"")
A28: 46347 | B28: 4 | C28: Base | D28: Sat | E28: 5K time trial | F28: 2 km easy + 4 strides · 5 km hard at an even effort · 1.5 km easy. Enter your time in Paces to set your VDOT for the Build phase. | G28: 8.8 | H28: =IF(C28="Base",'Start here'!$B$7,IF(C28="Build",'Start here'!$B$14,'Start here'!$B$15)) -> 32 | I28: =IF(Q28="","",IF(Q28="E","HR under "&ROUND('Start here'!$B$6*0.79,0),IF(Q28="REC","HR under "&ROUND('Start here'!$B$6*0.76,0),IF(Q28="L","HR "&ROUND('Start here'!$B$6*0.73,0)&" to "&ROUND('Start here'!$B$6*0.84,0),INDEX(Paces!$B$5:$K$15,MATCH(H28,Paces!$A$5:$A$15,0),MATCH(Q28,Paces!$B$4:$K$4,0)))))) | O28: =IF(AND(N(K28)>0,N(L28)>0),L28/K28,"")
A29: 46348 | B29: 4 | C29: Base | D29: Sun | E29: Recovery | F29: Recovery 30 min | G29: 3.6 | H29: =IF(C29="Base",'Start here'!$B$7,IF(C29="Build",'Start here'!$B$14,'Start here'!$B$15)) -> 32 | I29: =IF(Q29="","",IF(Q29="E","HR under "&ROUND('Start here'!$B$6*0.79,0),IF(Q29="REC","HR under "&ROUND('Start here'!$B$6*0.76,0),IF(Q29="L","HR "&ROUND('Start here'!$B$6*0.73,0)&" to "&ROUND('Start here'!$B$6*0.84,0),INDEX(Paces!$B$5:$K$15,MATCH(H29,Paces!$A$5:$A$15,0),MATCH(Q29,Paces!$B$4:$K$4,0)))))) -> HR under 147 | O29: =IF(AND(N(K29)>0,N(L29)>0),L29/K29,"") | Q29: REC
A30: 46349 | B30: 5 | C30: Build | D30: Mon | E30: Rest | F30: Rest day. Optional 10 min core at home on Mon or Fri. | H30: =IF(C30="Base",'Start here'!$B$7,IF(C30="Build",'Start here'!$B$14,'Start here'!$B$15)) -> 32 | I30: =IF(Q30="","",IF(Q30="E","HR under "&ROUND('Start here'!$B$6*0.79,0),IF(Q30="REC","HR under "&ROUND('Start here'!$B$6*0.76,0),IF(Q30="L","HR "&ROUND('Start here'!$B$6*0.73,0)&" to "&ROUND('Start here'!$B$6*0.84,0),INDEX(Paces!$B$5:$K$15,MATCH(H30,Paces!$A$5:$A$15,0),MATCH(Q30,Paces!$B$4:$K$4,0)))))) | O30: =IF(AND(N(K30)>0,N(L30)>0),L30/K30,"")
A31: 46350 | B31: 5 | C31: Build | D31: Tue | E31: Threshold | F31: 2 km easy · 3 × 7 min at T, 1 min jog · 1.5 km easy | G31: 7.2 | H31: =IF(C31="Base",'Start here'!$B$7,IF(C31="Build",'Start here'!$B$14,'Start here'!$B$15)) -> 32 | I31: =IF(Q31="","",IF(Q31="E","HR under "&ROUND('Start here'!$B$6*0.79,0),IF(Q31="REC","HR under "&ROUND('Start here'!$B$6*0.76,0),IF(Q31="L","HR "&ROUND('Start here'!$B$6*0.73,0)&" to "&ROUND('Start here'!$B$6*0.84,0),INDEX(Paces!$B$5:$K$15,MATCH(H31,Paces!$A$5:$A$15,0),MATCH(Q31,Paces!$B$4:$K$4,0)))))) -> 6:05/km | O31: =IF(AND(N(K31)>0,N(L31)>0),L31/K31,"") | Q31: T pace
A32: 46351 | B32: 5 | C32: Build | D32: Wed | E32: Easy + hill sprints | F32: Easy 40 min + 8 hill sprints (8 s) | G32: 5 | H32: =IF(C32="Base",'Start here'!$B$7,IF(C32="Build",'Start here'!$B$14,'Start here'!$B$15)) -> 32 | I32: =IF(Q32="","",IF(Q32="E","HR under "&ROUND('Start here'!$B$6*0.79,0),IF(Q32="REC","HR under "&ROUND('Start here'!$B$6*0.76,0),IF(Q32="L","HR "&ROUND('Start here'!$B$6*0.73,0)&" to "&ROUND('Start here'!$B$6*0.84,0),INDEX(Paces!$B$5:$K$15,MATCH(H32,Paces!$A$5:$A$15,0),MATCH(Q32,Paces!$B$4:$K$4,0)))))) -> HR under 153 | O32: =IF(AND(N(K32)>0,N(L32)>0),L32/K32,"") | Q32: E
A33: 46352 | B33: 5 | C33: Build | D33: Thu | E33: R session | F33: 2 km easy · 8 × 200 m at R, 200 m jog · 1.5 km easy | G33: 6.7 | H33: =IF(C33="Base",'Start here'!$B$7,IF(C33="Build",'Start here'!$B$14,'Start here'!$B$15)) -> 32 | I33: =IF(Q33="","",IF(Q33="E","HR under "&ROUND('Start here'!$B$6*0.79,0),IF(Q33="REC","HR under "&ROUND('Start here'!$B$6*0.76,0),IF(Q33="L","HR "&ROUND('Start here'!$B$6*0.73,0)&" to "&ROUND('Start here'!$B$6*0.84,0),INDEX(Paces!$B$5:$K$15,MATCH(H33,Paces!$A$5:$A$15,0),MATCH(Q33,Paces!$B$4:$K$4,0)))))) -> 63 s per 200 m | O33: =IF(AND(N(K33)>0,N(L33)>0),L33/K33,"") | Q33: R 200 m
A34: 46353 | B34: 5 | C34: Build | D34: Fri | E34: Rest | F34: Rest day. Optional 10 min core at home on Mon or Fri. | H34: =IF(C34="Base",'Start here'!$B$7,IF(C34="Build",'Start here'!$B$14,'Start here'!$B$15)) -> 32 | I34: =IF(Q34="","",IF(Q34="E","HR under "&ROUND('Start here'!$B$6*0.79,0),IF(Q34="REC","HR under "&ROUND('Start here'!$B$6*0.76,0),IF(Q34="L","HR "&ROUND('Start here'!$B$6*0.73,0)&" to "&ROUND('Start here'!$B$6*0.84,0),INDEX(Paces!$B$5:$K$15,MATCH(H34,Paces!$A$5:$A$15,0),MATCH(Q34,Paces!$B$4:$K$4,0)))))) | O34: =IF(AND(N(K34)>0,N(L34)>0),L34/K34,"")
A35: 46354 | B35: 5 | C35: Build | D35: Sat | E35: Long run | F35: Long 13 km easy | G35: 13 | H35: =IF(C35="Base",'Start here'!$B$7,IF(C35="Build",'Start here'!$B$14,'Start here'!$B$15)) -> 32 | I35: =IF(Q35="","",IF(Q35="E","HR under "&ROUND('Start here'!$B$6*0.79,0),IF(Q35="REC","HR under "&ROUND('Start here'!$B$6*0.76,0),IF(Q35="L","HR "&ROUND('Start here'!$B$6*0.73,0)&" to "&ROUND('Start here'!$B$6*0.84,0),INDEX(Paces!$B$5:$K$15,MATCH(H35,Paces!$A$5:$A$15,0),MATCH(Q35,Paces!$B$4:$K$4,0)))))) -> HR 142 to 163 | O35: =IF(AND(N(K35)>0,N(L35)>0),L35/K35,"") | Q35: L
A36: 46355 | B36: 5 | C36: Build | D36: Sun | E36: Recovery + strides | F36: Recovery 35 min + 6 strides | G36: 4.6 | H36: =IF(C36="Base",'Start here'!$B$7,IF(C36="Build",'Start here'!$B$14,'Start here'!$B$15)) -> 32 | I36: =IF(Q36="","",IF(Q36="E","HR under "&ROUND('Start here'!$B$6*0.79,0),IF(Q36="REC","HR under "&ROUND('Start here'!$B$6*0.76,0),IF(Q36="L","HR "&ROUND('Start here'!$B$6*0.73,0)&" to "&ROUND('Start here'!$B$6*0.84,0),INDEX(Paces!$B$5:$K$15,MATCH(H36,Paces!$A$5:$A$15,0),MATCH(Q36,Paces!$B$4:$K$4,0)))))) -> HR under 147 | O36: =IF(AND(N(K36)>0,N(L36)>0),L36/K36,"") | Q36: REC
A37: 46356 | B37: 6 | C37: Build | D37: Mon | E37: Rest | F37: Rest day. Optional 10 min core at home on Mon or Fri. | H37: =IF(C37="Base",'Start here'!$B$7,IF(C37="Build",'Start here'!$B$14,'Start here'!$B$15)) -> 32 | I37: =IF(Q37="","",IF(Q37="E","HR under "&ROUND('Start here'!$B$6*0.79,0),IF(Q37="REC","HR under "&ROUND('Start here'!$B$6*0.76,0),IF(Q37="L","HR "&ROUND('Start here'!$B$6*0.73,0)&" to "&ROUND('Start here'!$B$6*0.84,0),INDEX(Paces!$B$5:$K$15,MATCH(H37,Paces!$A$5:$A$15,0),MATCH(Q37,Paces!$B$4:$K$4,0)))))) | O37: =IF(AND(N(K37)>0,N(L37)>0),L37/K37,"")
A38: 46357 | B38: 6 | C38: Build | D38: Tue | E38: Threshold | F38: 2 km easy · 2 × 10 min at T, 2 min jog · 1.5 km easy | G38: 7 | H38: =IF(C38="Base",'Start here'!$B$7,IF(C38="Build",'Start here'!$B$14,'Start here'!$B$15)) -> 32 | I38: =IF(Q38="","",IF(Q38="E","HR under "&ROUND('Start here'!$B$6*0.79,0),IF(Q38="REC","HR under "&ROUND('Start here'!$B$6*0.76,0),IF(Q38="L","HR "&ROUND('Start here'!$B$6*0.73,0)&" to "&ROUND('Start here'!$B$6*0.84,0),INDEX(Paces!$B$5:$K$15,MATCH(H38,Paces!$A$5:$A$15,0),MATCH(Q38,Paces!$B$4:$K$4,0)))))) -> 6:05/km | O38: =IF(AND(N(K38)>0,N(L38)>0),L38/K38,"") | Q38: T pace
A39: 46358 | B39: 6 | C39: Build | D39: Wed | E39: Easy + hill sprints | F39: Easy 40 min + 8 hill sprints (10 s) | G39: 5.1 | H39: =IF(C39="Base",'Start here'!$B$7,IF(C39="Build",'Start here'!$B$14,'Start here'!$B$15)) -> 32 | I39: =IF(Q39="","",IF(Q39="E","HR under "&ROUND('Start here'!$B$6*0.79,0),IF(Q39="REC","HR under "&ROUND('Start here'!$B$6*0.76,0),IF(Q39="L","HR "&ROUND('Start here'!$B$6*0.73,0)&" to "&ROUND('Start here'!$B$6*0.84,0),INDEX(Paces!$B$5:$K$15,MATCH(H39,Paces!$A$5:$A$15,0),MATCH(Q39,Paces!$B$4:$K$4,0)))))) -> HR under 153 | O39: =IF(AND(N(K39)>0,N(L39)>0),L39/K39,"") | Q39: E
A40: 46359 | B40: 6 | C40: Build | D40: Thu | E40: I session | F40: 2 km easy · 4 × 4 min at I, 3 min jog · 1.5 km easy | G40: 7.5 | H40: =IF(C40="Base",'Start here'!$B$7,IF(C40="Build",'Start here'!$B$14,'Start here'!$B$15)) -> 32 | I40: =IF(Q40="","",IF(Q40="E","HR under "&ROUND('Start here'!$B$6*0.79,0),IF(Q40="REC","HR under "&ROUND('Start here'!$B$6*0.76,0),IF(Q40="L","HR "&ROUND('Start here'!$B$6*0.73,0)&" to "&ROUND('Start here'!$B$6*0.84,0),INDEX(Paces!$B$5:$K$15,MATCH(H40,Paces!$A$5:$A$15,0),MATCH(Q40,Paces!$B$4:$K$4,0)))))) -> 5:35/km (2:14 per 400 m) | O40: =IF(AND(N(K40)>0,N(L40)>0),L40/K40,"") | Q40: I pace
...

Sheet Weekly
A1: Planned and logged distance by week
A2: Updates from the Done and Actual km columns on the Plan sheet. Week 15 includes the race (21.1 km).
A4: Week | B4: Phase | C4: From | D4: To | E4: Planned km | F4: Runs planned | G4: Runs done | H4: Logged km | I4: Logged / planned
A5: 1 | B5: Base | C5: 46321 | D5: 46327 | E5: =SUMIFS(Plan!$G$2:$G$105,Plan!$B$2:$B$105,A5) -> 31.2 | F5: =COUNTIFS(Plan!$B$2:$B$105,A5,Plan!$E$2:$E$105,"<>Rest") -> 5 | G5: =COUNTIFS(Plan!$B$2:$B$105,A5,Plan!$J$2:$J$105,"Yes") -> 0 | H5: =SUMIFS(Plan!$K$2:$K$105,Plan!$B$2:$B$105,A5,Plan!$J$2:$J$105,"Yes") -> 0 | I5: =IF(E5>0,H5/E5,0) -> 0
A6: 2 | B6: Base | C6: 46328 | D6: 46334 | E6: =SUMIFS(Plan!$G$2:$G$105,Plan!$B$2:$B$105,A6) -> 32.2 | F6: =COUNTIFS(Plan!$B$2:$B$105,A6,Plan!$E$2:$E$105,"<>Rest") -> 5 | G6: =COUNTIFS(Plan!$B$2:$B$105,A6,Plan!$J$2:$J$105,"Yes") -> 0 | H6: =SUMIFS(Plan!$K$2:$K$105,Plan!$B$2:$B$105,A6,Plan!$J$2:$J$105,"Yes") -> 0 | I6: =IF(E6>0,H6/E6,0) -> 0
A7: 3 | B7: Base | C7: 46335 | D7: 46341 | E7: =SUMIFS(Plan!$G$2:$G$105,Plan!$B$2:$B$105,A7) -> 34 | F7: =COUNTIFS(Plan!$B$2:$B$105,A7,Plan!$E$2:$E$105,"<>Rest") -> 5 | G7: =COUNTIFS(Plan!$B$2:$B$105,A7,Plan!$J$2:$J$105,"Yes") -> 0 | H7: =SUMIFS(Plan!$K$2:$K$105,Plan!$B$2:$B$105,A7,Plan!$J$2:$J$105,"Yes") -> 0 | I7: =IF(E7>0,H7/E7,0) -> 0
A8: 4 | B8: Base | C8: 46342 | D8: 46348 | E8: =SUMIFS(Plan!$G$2:$G$105,Plan!$B$2:$B$105,A8) -> 27.6 | F8: =COUNTIFS(Plan!$B$2:$B$105,A8,Plan!$E$2:$E$105,"<>Rest") -> 5 | G8: =COUNTIFS(Plan!$B$2:$B$105,A8,Plan!$J$2:$J$105,"Yes") -> 0 | H8: =SUMIFS(Plan!$K$2:$K$105,Plan!$B$2:$B$105,A8,Plan!$J$2:$J$105,"Yes") -> 0 | I8: =IF(E8>0,H8/E8,0) -> 0
A9: 5 | B9: Build | C9: 46349 | D9: 46355 | E9: =SUMIFS(Plan!$G$2:$G$105,Plan!$B$2:$B$105,A9) -> 36.5 | F9: =COUNTIFS(Plan!$B$2:$B$105,A9,Plan!$E$2:$E$105,"<>Rest") -> 5 | G9: =COUNTIFS(Plan!$B$2:$B$105,A9,Plan!$J$2:$J$105,"Yes") -> 0 | H9: =SUMIFS(Plan!$K$2:$K$105,Plan!$B$2:$B$105,A9,Plan!$J$2:$J$105,"Yes") -> 0 | I9: =IF(E9>0,H9/E9,0) -> 0
A10: 6 | B10: Build | C10: 46356 | D10: 46362 | E10: =SUMIFS(Plan!$G$2:$G$105,Plan!$B$2:$B$105,A10) -> 37.2 | F10: =COUNTIFS(Plan!$B$2:$B$105,A10,Plan!$E$2:$E$105,"<>Rest") -> 5 | G10: =COUNTIFS(Plan!$B$2:$B$105,A10,Plan!$J$2:$J$105,"Yes") -> 0 | H10: =SUMIFS(Plan!$K$2:$K$105,Plan!$B$2:$B$105,A10,Plan!$J$2:$J$105,"Yes") -> 0 | I10: =IF(E10>0,H10/E10,0) -> 0
A11: 7 | B11: Build | C11: 46363 | D11: 46369 | E11: =SUMIFS(Plan!$G$2:$G$105,Plan!$B$2:$B$105,A11) -> 38.5 | F11: =COUNTIFS(Plan!$B$2:$B$105,A11,Plan!$E$2:$E$105,"<>Rest") -> 5 | G11: =COUNTIFS(Plan!$B$2:$B$105,A11,Plan!$J$2:$J$105,"Yes") -> 0 | H11: =SUMIFS(Plan!$K$2:$K$105,Plan!$B$2:$B$105,A11,Plan!$J$2:$J$105,"Yes") -> 0 | I11: =IF(E11>0,H11/E11,0) -> 0
A12: 8 | B12: Build | C12: 46370 | D12: 46376 | E12: =SUMIFS(Plan!$G$2:$G$105,Plan!$B$2:$B$105,A12) -> 33.1 | F12: =COUNTIFS(Plan!$B$2:$B$105,A12,Plan!$E$2:$E$105,"<>Rest") -> 5 | G12: =COUNTIFS(Plan!$B$2:$B$105,A12,Plan!$J$2:$J$105,"Yes") -> 0 | H12: =SUMIFS(Plan!$K$2:$K$105,Plan!$B$2:$B$105,A12,Plan!$J$2:$J$105,"Yes") -> 0 | I12: =IF(E12>0,H12/E12,0) -> 0
A13: 9 | B13: Build | C13: 46377 | D13: 46383 | E13: =SUMIFS(Plan!$G$2:$G$105,Plan!$B$2:$B$105,A13) -> 35.8 | F13: =COUNTIFS(Plan!$B$2:$B$105,A13,Plan!$E$2:$E$105,"<>Rest") -> 5 | G13: =COUNTIFS(Plan!$B$2:$B$105,A13,Plan!$J$2:$J$105,"Yes") -> 0 | H13: =SUMIFS(Plan!$K$2:$K$105,Plan!$B$2:$B$105,A13,Plan!$J$2:$J$105,"Yes") -> 0 | I13: =IF(E13>0,H13/E13,0) -> 0
A14: 10 | B14: Race-specific | C14: 46384 | D14: 46390 | E14: =SUMIFS(Plan!$G$2:$G$105,Plan!$B$2:$B$105,A14) -> 40.1 | F14: =COUNTIFS(Plan!$B$2:$B$105,A14,Plan!$E$2:$E$105,"<>Rest") -> 5 | G14: =COUNTIFS(Plan!$B$2:$B$105,A14,Plan!$J$2:$J$105,"Yes") -> 0 | H14: =SUMIFS(Plan!$K$2:$K$105,Plan!$B$2:$B$105,A14,Plan!$J$2:$J$105,"Yes") -> 0 | I14: =IF(E14>0,H14/E14,0) -> 0
A15: 11 | B15: Race-specific | C15: 46391 | D15: 46397 | E15: =SUMIFS(Plan!$G$2:$G$105,Plan!$B$2:$B$105,A15) -> 39.8 | F15: =COUNTIFS(Plan!$B$2:$B$105,A15,Plan!$E$2:$E$105,"<>Rest") -> 5 | G15: =COUNTIFS(Plan!$B$2:$B$105,A15,Plan!$J$2:$J$105,"Yes") -> 0 | H15: =SUMIFS(Plan!$K$2:$K$105,Plan!$B$2:$B$105,A15,Plan!$J$2:$J$105,"Yes") -> 0 | I15: =IF(E15>0,H15/E15,0) -> 0
A16: 12 | B16: Race-specific | C16: 46398 | D16: 46404 | E16: =SUMIFS(Plan!$G$2:$G$105,Plan!$B$2:$B$105,A16) -> 41.1 | F16: =COUNTIFS(Plan!$B$2:$B$105,A16,Plan!$E$2:$E$105,"<>Rest") -> 5 | G16: =COUNTIFS(Plan!$B$2:$B$105,A16,Plan!$J$2:$J$105,"Yes") -> 0 | H16: =SUMIFS(Plan!$K$2:$K$105,Plan!$B$2:$B$105,A16,Plan!$J$2:$J$105,"Yes") -> 0 | I16: =IF(E16>0,H16/E16,0) -> 0
... A19: 15 | B19: Taper & race | C19: 46419 | D19: 46424 | E19: =SUMIFS(Plan!$G$2:$G$105,Plan!$B$2:$B$105,A19) -> 37.5 | F19: =COUNTIFS(Plan!$B$2:$B$105,A19,Plan!$E$2:$E$105,"<>Rest") -> 6 | G19: =COUNTIFS(Plan!$B$2:$B$105,A19,Plan!$J$2:$J$105,"Yes") -> 0 | H19: =SUMIFS(Plan!$K$2:$K$105,Plan!$B$2:$B$105,A19,Plan!$J$2:$J$105,"Yes") -> 0 | I19: =IF(E19>0,H19/E19,0) -> 0
A20: Total | E20: =SUM(E5:E19) -> 531.4 | F20: =SUM(F5:F19) -> 76 | G20: =SUM(G5:G19) -> 0 | H20: =SUM(H5:H19) -> 0 | I20: =IF(E20>0,H20/E20,0) -> 0

Sheet Paces
A1: Training paces and race times by VDOT
A2: Source: Daniels' Running Formula, 4th ed., tables 5.1 (race times) and 5.2 (training paces). HM pace = half-marathon time ÷ 21.0975 km.
A4: VDOT | B4: 5K | C4: 10K | D4: Half | E4: HM pace | F4: T pace | G4: I pace | H4: R 200 m | I4: R 300 m | J4: M pace | K4: Easy (Daniels)
A5: 30 | B5: 0.021296296 | C5: 0.044282407 | D5: 0.097962963 | E5: =INT(ROUND(D5*86400/21.0975,0)/60)&":"&TEXT(MOD(ROUND(D5*86400/21.0975,0),60),"00")&"/km" -> 6:41/km | F5: 6:24/km | G5: 5:55/km (2:22 per 400 m) | H5: 67 s per 200 m | I5: 101 s per 300 m | J5: 7:03/km | K5: 7:27–8:14/km
A6: 31 | B6: 0.020729167 | C6: 0.043090278 | D6: 0.095381944 | E6: =INT(ROUND(D6*86400/21.0975,0)/60)&":"&TEXT(MOD(ROUND(D6*86400/21.0975,0),60),"00")&"/km" -> 6:31/km | F6: 6:14/km | G6: 5:45/km (2:18 per 400 m) | H6: 65 s per 200 m | I6: 98 s per 300 m | J6: 6:52/km | K6: 7:16–8:02/km
A7: 32 | B7: 0.020196759 | C7: 0.041967593 | D7: 0.092928241 | E7: =INT(ROUND(D7*86400/21.0975,0)/60)&":"&TEXT(MOD(ROUND(D7*86400/21.0975,0),60),"00")&"/km" -> 6:21/km | F7: 6:05/km | G7: 5:35/km (2:14 per 400 m) | H7: 63 s per 200 m | I7: 95 s per 300 m | J7: 6:40/km | K7: 7:05–7:52/km
A8: 33 | B8: 0.0196875 | C8: 0.040902778 | D8: 0.090590278 | E8: =INT(ROUND(D8*86400/21.0975,0)/60)&":"&TEXT(MOD(ROUND(D8*86400/21.0975,0),60),"00")&"/km" -> 6:11/km | F8: 5:56/km | G8: 5:28/km (2:11 per 400 m) | H8: 61 s per 200 m | I8: 92 s per 300 m | J8: 6:30/km | K8: 6:55–7:41/km
A9: 34 | B9: 0.019201389 | C9: 0.039884259 | D9: 0.08837963 | E9: =INT(ROUND(D9*86400/21.0975,0)/60)&":"&TEXT(MOD(ROUND(D9*86400/21.0975,0),60),"00")&"/km" -> 6:02/km | F9: 5:48/km | G9: 5:20/km (2:08 per 400 m) | H9: 60 s per 200 m | I9: 90 s per 300 m | J9: 6:20/km | K9: 6:45–7:31/km
A10: 35 | B10: 0.01875 | C10: 0.038923611 | D10: 0.086261574 | E10: =INT(ROUND(D10*86400/21.0975,0)/60)&":"&TEXT(MOD(ROUND(D10*86400/21.0975,0),60),"00")&"/km" -> 5:53/km | F10: 5:40/km | G10: 5:13/km (2:05 per 400 m) | H10: 58 s per 200 m | I10: 87 s per 300 m | J10: 6:10/km | K10: 6:36–7:21/km
A11: 36 | B11: 0.018310185 | C11: 0.038009259 | D11: 0.084247685 | E11: =INT(ROUND(D11*86400/21.0975,0)/60)&":"&TEXT(MOD(ROUND(D11*86400/21.0975,0),60),"00")&"/km" -> 5:45/km | F11: 5:33/km | G11: 5:05/km (2:02 per 400 m) | H11: 57 s per 200 m | I11: 85 s per 300 m | J11: 6:01/km | K11: 6:27–7:11/km
A12: 37 | B12: 0.017893519 | C12: 0.037141204 | D12: 0.082337963 | E12: =INT(ROUND(D12*86400/21.0975,0)/60)&":"&TEXT(MOD(ROUND(D12*86400/21.0975,0),60),"00")&"/km" -> 5:37/km | F12: 5:26/km | G12: 5:00/km (1:59 per 400 m) | H12: 55 s per 200 m | I12: 83 s per 300 m | J12: 5:53/km | K12: 6:19–7:02/km
A13: 38 | B13: 0.0175 | C13: 0.03630787 | D13: 0.080497685 | E13: =INT(ROUND(D13*86400/21.0975,0)/60)&":"&TEXT(MOD(ROUND(D13*86400/21.0975,0),60),"00")&"/km" -> 5:30/km | F13: 5:19/km | G13: 4:54/km (1:56 per 400 m) | H13: 54 s per 200 m | I13: 81 s per 300 m | J13: 5:45/km | K13: 6:11–6:54/km
A14: 39 | B14: 0.017118056 | C14: 0.035520833 | D14: 0.07875 | E14: =INT(ROUND(D14*86400/21.0975,0)/60)&":"&TEXT(MOD(ROUND(D14*86400/21.0975,0),60),"00")&"/km" -> 5:23/km | F14: 5:12/km | G14: 4:48/km (1:54 per 400 m) | H14: 53 s per 200 m | I14: 80 s per 300 m | J14: 5:37/km | K14: 6:03–6:46/km
A15: 40 | B15: 0.016759259 | C15: 0.034756944 | D15: 0.077071759 | E15: =INT(ROUND(D15*86400/21.0975,0)/60)&":"&TEXT(MOD(ROUND(D15*86400/21.0975,0),60),"00")&"/km" -> 5:16/km | F15: 5:06/km | G15: 4:42/km (1:52 per 400 m) | H15: 52 s per 200 m | I15: 78 s per 300 m | J15: 5:29/km | K15: 5:56–6:38/km

Sheet Gym
A1: Gym A: heavy (Sunday, after the recovery run, about 40 min)
A2: Exercise | B2: Sets × reps | C2: Notes
A3: Squat (back or goblet) or trap-bar deadlift | B3: 3 × 5 | C3: Heavy: you could do only about 2 more
A4: Romanian deadlift | B4: 3 × 6
A5: Bulgarian split squat | B5: 3 × 6 per leg
A6: Standing calf raise | B6: 3 × 8 | C6: Heavy
A7: Bent-knee calf raise | B7: 3 × 10 | C7: Works the soleus
A8: Core: plank, side plank, dead bug | B8: 2 rounds
A10: Gym B: power (Wednesday, after the easy run, about 25 min)
A11: Exercise | B11: Sets × reps | C11: Notes
A12: Pogo hops | B12: 3 × 20 contacts | C12: Quick, stiff ankles
A13: Box jumps | B13: 3 × 5 | C13: Step down, don't jump down
A14: Bounding | B14: 3 × 20 m | C14: From week 5
A15: Single-leg Romanian deadlift | B15: 3 × 8 per leg
A16: Isometric hold (optional) | B16: 6 × 5 s | C16: Push hard against a fixed bar, split-squat or calf-raise position
A17: Core: plank, side plank, dead bug | B17: 2 rounds
A19: How the gym work progresses
A20: Weeks | B20: What to do
A21: 1–2 | B21: Learn the movements | C21: Moderate weights, 3 × 8 in Gym A
A22: 3–9 | B22: Go heavy | C22: 3 × 4–6; skip the sessions marked in test weeks 4 and 8
A23: 10–13 | B23: Maintain | C23: Same weights, 2 sets; half the jumps in Gym B
A24: 14–15 | B24: Taper | C24: Core only in week 14, nothing in race week
A26: Hill sprints and strides
A27: What | B27: How | C27: Progression
A28: Hill sprints (Hudson, Snow) | B28: 6–8% hill, 8–10 s all-out, walk down, rest at least 3 min | C28: 2, 4, 6 × 8 s (weeks 1–3); 8 × 8 s (week 5); 8 × 10 s (weeks 6–7); 6 × 10 s to Jan 20
A29: Strides (Daniels) | B29: 15–20 s light and quick at about R pace; 45–60 s easy between | C29: Never a sprint
A31: Sources: Pfitzinger & Douglas, Advanced Marathoning; Hudson & Fitzgerald, Run Faster; Snow, Run Elite; Llanos-Lagos et al. 2024 (Sports Medicine).
